2020-10-26 19:27:32,572 ERROR: Exception on / [GET] [in /Users/alessandrofranca/opt/anaconda3/envs/bigTutorialFlask/lib/python3.8/site-packages/flask/app.py:1758]
Traceback (most recent call last):
  File "/Users/alessandrofranca/opt/anaconda3/envs/bigTutorialFlask/lib/python3.8/site-packages/sqlalchemy/engine/base.py", line 1178, in _execute_context
    self.dialect.do_execute(
  File "/Users/alessandrofranca/opt/anaconda3/envs/bigTutorialFlask/lib/python3.8/site-packages/sqlalchemy/engine/default.py", line 470, in do_execute
    cursor.execute(statement, parameters)
sqlite3.OperationalError: no such table: user

The above exception was the direct cause of the following exception:

Traceback (most recent call last):
  File "/Users/alessandrofranca/opt/anaconda3/envs/bigTutorialFlask/lib/python3.8/site-packages/flask/app.py", line 2292, in wsgi_app
    response = self.full_dispatch_request()
  File "/Users/alessandrofranca/opt/anaconda3/envs/bigTutorialFlask/lib/python3.8/site-packages/flask/app.py", line 1815, in full_dispatch_request
    rv = self.handle_user_exception(e)
  File "/Users/alessandrofranca/opt/anaconda3/envs/bigTutorialFlask/lib/python3.8/site-packages/flask/app.py", line 1718, in handle_user_exception
    reraise(exc_type, exc_value, tb)
  File "/Users/alessandrofranca/opt/anaconda3/envs/bigTutorialFlask/lib/python3.8/site-packages/flask/_compat.py", line 35, in reraise
    raise value
  File "/Users/alessandrofranca/opt/anaconda3/envs/bigTutorialFlask/lib/python3.8/site-packages/flask/app.py", line 1811, in full_dispatch_request
    rv = self.preprocess_request()
  File "/Users/alessandrofranca/opt/anaconda3/envs/bigTutorialFlask/lib/python3.8/site-packages/flask/app.py", line 2087, in preprocess_request
    rv = func()
  File "/Users/alessandrofranca/Downloads/microblog-0.15/app/main/routes.py", line 16, in before_request
    if current_user.is_authenticated:
  File "/Users/alessandrofranca/opt/anaconda3/envs/bigTutorialFlask/lib/python3.8/site-packages/werkzeug/local.py", line 347, in __getattr__
    return getattr(self._get_current_object(), name)
  File "/Users/alessandrofranca/opt/anaconda3/envs/bigTutorialFlask/lib/python3.8/site-packages/werkzeug/local.py", line 306, in _get_current_object
    return self.__local()
  File "/Users/alessandrofranca/opt/anaconda3/envs/bigTutorialFlask/lib/python3.8/site-packages/flask_login/utils.py", line 26, in <lambda>
    current_user = LocalProxy(lambda: _get_user())
  File "/Users/alessandrofranca/opt/anaconda3/envs/bigTutorialFlask/lib/python3.8/site-packages/flask_login/utils.py", line 302, in _get_user
    current_app.login_manager._load_user()
  File "/Users/alessandrofranca/opt/anaconda3/envs/bigTutorialFlask/lib/python3.8/site-packages/flask_login/login_manager.py", line 317, in _load_user
    return self.reload_user()
  File "/Users/alessandrofranca/opt/anaconda3/envs/bigTutorialFlask/lib/python3.8/site-packages/flask_login/login_manager.py", line 279, in reload_user
    user = self.user_callback(user_id)
  File "/Users/alessandrofranca/Downloads/microblog-0.15/app/models.py", line 83, in load_user
    return User.query.get(int(id))
  File "/Users/alessandrofranca/opt/anaconda3/envs/bigTutorialFlask/lib/python3.8/site-packages/sqlalchemy/orm/query.py", line 864, in get
    return self._get_impl(ident, loading.load_on_ident)
  File "/Users/alessandrofranca/opt/anaconda3/envs/bigTutorialFlask/lib/python3.8/site-packages/sqlalchemy/orm/query.py", line 897, in _get_impl
    return fallback_fn(self, key)
  File "/Users/alessandrofranca/opt/anaconda3/envs/bigTutorialFlask/lib/python3.8/site-packages/sqlalchemy/orm/loading.py", line 223, in load_on_ident
    return q.one()
  File "/Users/alessandrofranca/opt/anaconda3/envs/bigTutorialFlask/lib/python3.8/site-packages/sqlalchemy/orm/query.py", line 2814, in one
    ret = self.one_or_none()
  File "/Users/alessandrofranca/opt/anaconda3/envs/bigTutorialFlask/lib/python3.8/site-packages/sqlalchemy/orm/query.py", line 2784, in one_or_none
    ret = list(self)
  File "/Users/alessandrofranca/opt/anaconda3/envs/bigTutorialFlask/lib/python3.8/site-packages/sqlalchemy/orm/query.py", line 2855, in __iter__
    return self._execute_and_instances(context)
  File "/Users/alessandrofranca/opt/anaconda3/envs/bigTutorialFlask/lib/python3.8/site-packages/sqlalchemy/orm/query.py", line 2878, in _execute_and_instances
    result = conn.execute(querycontext.statement, self._params)
  File "/Users/alessandrofranca/opt/anaconda3/envs/bigTutorialFlask/lib/python3.8/site-packages/sqlalchemy/engine/base.py", line 945, in execute
    return meth(self, multiparams, params)
  File "/Users/alessandrofranca/opt/anaconda3/envs/bigTutorialFlask/lib/python3.8/site-packages/sqlalchemy/sql/elements.py", line 263, in _execute_on_connection
    return connection._execute_clauseelement(self, multiparams, params)
  File "/Users/alessandrofranca/opt/anaconda3/envs/bigTutorialFlask/lib/python3.8/site-packages/sqlalchemy/engine/base.py", line 1048, in _execute_clauseelement
    ret = self._execute_context(
  File "/Users/alessandrofranca/opt/anaconda3/envs/bigTutorialFlask/lib/python3.8/site-packages/sqlalchemy/engine/base.py", line 1184, in _execute_context
    self._handle_dbapi_exception(
  File "/Users/alessandrofranca/opt/anaconda3/envs/bigTutorialFlask/lib/python3.8/site-packages/sqlalchemy/engine/base.py", line 1400, in _handle_dbapi_exception
    util.raise_from_cause(
  File "/Users/alessandrofranca/opt/anaconda3/envs/bigTutorialFlask/lib/python3.8/site-packages/sqlalchemy/util/compat.py", line 203, in raise_from_cause
    reraise(type(exception), exception, tb=exc_tb, cause=cause)
  File "/Users/alessandrofranca/opt/anaconda3/envs/bigTutorialFlask/lib/python3.8/site-packages/sqlalchemy/util/compat.py", line 186, in reraise
    raise value.with_traceback(tb)
  File "/Users/alessandrofranca/opt/anaconda3/envs/bigTutorialFlask/lib/python3.8/site-packages/sqlalchemy/engine/base.py", line 1178, in _execute_context
    self.dialect.do_execute(
  File "/Users/alessandrofranca/opt/anaconda3/envs/bigTutorialFlask/lib/python3.8/site-packages/sqlalchemy/engine/default.py", line 470, in do_execute
    cursor.execute(statement, parameters)
sqlalchemy.exc.OperationalError: (sqlite3.OperationalError) no such table: user [SQL: 'SELECT user.id AS user_id, user.username AS user_username, user.email AS user_email, user.password_hash AS user_password_hash, user.about_me AS user_about_me, user.last_seen AS user_last_seen \nFROM user \nWHERE user.id = ?'] [parameters: (1,)]
2020-10-28 16:44:29,949 INFO: Microblog startup [in /Users/alessandrofranca/Downloads/microblog-0.15/app/__init__.py:74]
2020-10-28 16:46:15,804 INFO: Microblog startup [in /Users/alessandrofranca/Downloads/microblog-0.15/app/__init__.py:74]
2020-10-28 16:46:43,744 INFO: Microblog startup [in /Users/alessandrofranca/Downloads/microblog-0.15/app/__init__.py:74]
2020-10-28 16:46:53,275 INFO: Microblog startup [in /Users/alessandrofranca/Downloads/microblog-0.15/app/__init__.py:74]
2020-10-28 16:47:12,998 INFO: Microblog startup [in /Users/alessandrofranca/Downloads/microblog-0.15/app/__init__.py:74]
2020-10-28 16:47:18,397 INFO: Microblog startup [in /Users/alessandrofranca/Downloads/microblog-0.15/app/__init__.py:74]
2020-10-28 16:52:17,301 INFO: Microblog startup [in /Users/alessandrofranca/Downloads/microblog-0.15/app/__init__.py:74]
2020-10-28 16:52:54,696 INFO: Microblog startup [in /Users/alessandrofranca/Downloads/microblog-0.15/app/__init__.py:74]
2020-10-28 16:55:22,731 INFO: Microblog startup [in /Users/alessandrofranca/Downloads/microblog-0.15/app/__init__.py:74]
2020-10-28 18:26:51,599 INFO: Microblog startup [in /Users/alessandrofranca/Downloads/microblog-0.15/app/__init__.py:74]
2020-11-02 18:25:54,363 INFO: Microblog startup [in /Users/alessandrofranca/Downloads/microblog-0.15/app/__init__.py:74]
2020-11-04 20:39:55,459 INFO: Microblog startup [in /Users/alessandrofranca/Downloads/microblog-0.15/app/__init__.py:74]
2020-11-12 16:57:04,393 INFO: Microblog startup [in /Users/alessandrofranca/Downloads/microblog-0.15/app/__init__.py:74]
2020-11-12 18:40:07,573 ERROR: Exception on /aggregator/getBaselines [POST] [in /Users/alessandrofranca/opt/anaconda3/envs/bigTutorialFlask/lib/python3.8/site-packages/flask/app.py:1758]
Traceback (most recent call last):
  File "/Users/alessandrofranca/opt/anaconda3/envs/bigTutorialFlask/lib/python3.8/site-packages/flask/app.py", line 2292, in wsgi_app
    response = self.full_dispatch_request()
  File "/Users/alessandrofranca/opt/anaconda3/envs/bigTutorialFlask/lib/python3.8/site-packages/flask/app.py", line 1815, in full_dispatch_request
    rv = self.handle_user_exception(e)
  File "/Users/alessandrofranca/opt/anaconda3/envs/bigTutorialFlask/lib/python3.8/site-packages/flask/app.py", line 1718, in handle_user_exception
    reraise(exc_type, exc_value, tb)
  File "/Users/alessandrofranca/opt/anaconda3/envs/bigTutorialFlask/lib/python3.8/site-packages/flask/_compat.py", line 35, in reraise
    raise value
  File "/Users/alessandrofranca/opt/anaconda3/envs/bigTutorialFlask/lib/python3.8/site-packages/flask/app.py", line 1813, in full_dispatch_request
    rv = self.dispatch_request()
  File "/Users/alessandrofranca/opt/anaconda3/envs/bigTutorialFlask/lib/python3.8/site-packages/flask/app.py", line 1799, in dispatch_request
    return self.view_functions[rule.endpoint](**req.view_args)
  File "/Users/alessandrofranca/opt/anaconda3/envs/bigTutorialFlask/lib/python3.8/site-packages/flask_login/utils.py", line 228, in decorated_view
    return func(*args, **kwargs)
  File "/Users/alessandrofranca/Downloads/microblog-0.15/app/main/routes.py", line 157, in getBaselines
    session['rendering'] = renderData(result)
  File "/Users/alessandrofranca/Downloads/microblog-0.15/app/main/routes.py", line 39, in renderData
    res += '{} :\n'.format(key, data[key][0]['subplants'])
IndexError: list index out of range
2020-11-13 18:40:37,529 INFO: Microblog startup [in /Users/alessandrofranca/Downloads/microblog-0.15/app/__init__.py:74]
2020-11-13 18:41:42,012 INFO: Microblog startup [in /Users/alessandrofranca/Downloads/microblog-0.15/app/__init__.py:74]
